<?xml version="1.0" encoding="UTF-8"?>
<mujoco model="mouse">
  <option integrator="RK4" timestep="0.01" gravity="0 0 -9.81" solver="CG" ls_iterations="20"></option>
  <default>
  <joint limited="true" solreflimit="0.01 1" solimplimit="0.99 0.9999 0" armature="4e-06" damping="0.001" stiffness="0.001"/>
	</default>
  <size njmax="1000" nconmax="400" nkey="1" nuser_jnt="1"/>
  <visual>
    <scale framelength="1.0" framewidth="0.02"/>
  </visual>
  <asset>
		<texture type="skybox" builtin="gradient" rgb1="1 1 1" rgb2="0.6 0.8 1" width="256" height="1536"/>
		<texture name="grid" type="2d" builtin="checker" width="512" height="512" rgb1=".1 .2 .3" rgb2=".2 .3 .4"/>
		<material name="grid" texture="grid" texrepeat="1 1" texuniform="true" reflectance=".2"/>
    <mesh file="/root/vast/eric/stac-mjx/meshes/stl/Bone_Clavicle_right_v3.stl"/>
    <mesh file="/root/vast/eric/stac-mjx/meshes/stl/Bone_Scapula_right_v3.stl"/>

    <mesh file="/root/vast/eric/stac-mjx/meshes/stl/Bone_Humerus_right_v3.stl"/>    <mesh file="/root/vast/eric/stac-mjx/meshes/stl/Bone_Ulna_right_v3.stl"/>
    <mesh file="/root/vast/eric/stac-mjx/meshes/stl/Bone_Radius_right_v3.stl"/>
    <mesh file="/root/vast/eric/stac-mjx/meshes/stl/Bone_Segments_Hand_fixed.stl"/> -->
  </asset>

  <worldbody>
    <light directional="true"/>
    <body name="ground" euler="0 0 0">
      <body name="clavicle" pos="0 0 0" euler="0 0 0 ">
        <camera name="my_camera" pos="0.04 .004 0.037" fovy="20" quat="0.6532815 0.2705981 0.2705981 0.6532815"/>


        <!-- <geom type="cylinder" size="0.2 0.5" pos="0 0 0.0005" contype="1" conaffinity="0"/> -->
        <geom type="mesh" mesh="Bone_Clavicle_right_v3" pos="0 0 0.0005" contype="1" conaffinity="0"/>


        <!--SOB Scapula-->
				<body name="scapula" pos="-0.0001 -0.0001 0.0005" euler="-30 -15 0">
					<!--Mesh Geom-->
					<geom type="mesh" mesh="Bone_Scapula_right_v3" pos="0.0 0.0 0.0" contype="1" conaffinity="0"/>
					
          <body name="humerus" pos="0 0.0007 -0.0002" euler="-15 0 0">						
						<!-- Glenohumeral (aka shoulder) Joint-->					
						<inertial pos="-0.0005 0.0003 -0.004" mass="0.0001258" diaginertia="3e-8 3e-8 3e-8"/>
												<!--Mesh Geom-->
						<geom type="mesh" mesh="Bone_Humerus_right_v3" pos="0.0 0.0 0.0" contype="1" conaffinity="0"/>

						<joint name="sh_elv" type="hinge" pos="0 0 0" axis="0 1 0" range="-70 0" limited="true"/>
						<!-- Extension Joint: Yaw around Z-axis -->
						<joint name="sh_extension" type="hinge" pos="0 0 0" axis="0 0 1" range="-70 40" limited="true"/>
						<!-- Rotation Joint: Roll around X-axis -->
						<joint name="sh_rotation" type="hinge" pos="0 0 0" axis="1 0 0" range="-25 89" limited="true"/>
            
            
            <!-- SOB Elbow -->
            <!-- <body name="elbow" pos="0.0 0.0 0.0" euler="0 0 0"> -->
            <body name="elbow" pos="-0.0005 0.0003 -0.0068" euler="0 0 0">

              <!-- elbow marker and joint -->
              <geom name="elbow_marker" type="sphere" size="0.001" pos="0 0 0" contype="0" conaffinity="0" rgba="0.3 0.8 0.3 0.8" />
              <joint name="elbow_joint" pos="0 0 0 " axis="1 0 0" range="-80 90" limited="true"/>
            
              <!--SOB Ulna-->
              <!-- <body name="ulna" pos="-0.0005 0.0003 -0.0068" euler="-15 0 0"> -->
              <body name="ulna" pos="0 0 0" euler="-15 0 0">
                <geom type="mesh" mesh="Bone_Ulna_right_v3" pos="0.0 0.0 0.0" contype="1" conaffinity="0"/>
                <geom type="box" size="0.0001 0.002 0.004" rgba="1 0 0 0.5"/>
                
                
                <!--SOB Radius--> 
                <body name="radius" pos="0.00035 0.0002 0.0002" euler="0 0 0">
                  <geom type="mesh" mesh="Bone_Radius_right_v3" pos="0.0 0.0 0.0" contype="1" conaffinity="0"/>
                  <body name="wrist_body" pos="-0.002 0.0065 0.0005" euler="0 0 0">
                    <geom name="wrist_marker" type="sphere" size="0.0008" pos="0.0 0.003 0.0" contype="0" conaffinity="0" rgba="0.3 0.8 0.3 0.8"/>
                    <geom name="hand_mesh_geom" type="mesh" mesh="Bone_Segments_Hand_fixed" contype="1" conaffinity="0" pos="0 0 0"/>					
                  </body>
                </body>
              </body>
                
            </body>

              
          </body>
				</body>


      </body>
    </body>
  </worldbody>
</mujoco>